<?xml version="1.0"?>
<robot name="mysecond">
  <!-- Material Colours -->
  <material name="blue">
    <color rgba="0 0 0.8 1"/>
  </material>
  <material name="black">
    <color rgba="0 0 0 1"/>
  </material>
  <material name="red">
    <color rgba="1 0 0 1"/>
  </material>

  <!-- Robot Torso -->
  <link name="base_link">
    <visual>
      <geometry>
        <sphere radius="0.4"/>
      </geometry>
      <material name="red"/>
    </visual>
    <collision>
      <geometry>
        <sphere radius="0.4"/>
      </geometry>
    </collision>
    <inertial>
      <mass value="0.20"/>
      <inertia
        ixx="0.0003"
        iyy="0.0003"
        izz="0.0003"
        ixy="0"
        ixz="0"
        iyz="0"
      />
    </inertial>
  </link>

  <!-- Robot 'arms' -->
  <link name="sub_link_1">
    <visual>
      <geometry>
        <cylinder length="2" radius="0.1"/>
      </geometry>
      <material name="blue"/>
    </visual>
    <collision>
      <geometry>
        <cylinder length="2" radius="0.1"/>
      </geometry>
    </collision>
    <inertial>
      <mass value="0.10"/>
      <inertia
        ixx="0.0002"
        iyy="0.0002"
        izz="0.0002"
        ixy="0"
        ixz="0"
        iyz="0"
      />
    </inertial>
  </link>

  <link name="sub_link_2">
    <visual>
      <geometry>
        <cylinder length="2" radius="0.1"/>
      </geometry>
      <material name="blue"/>
    </visual>
    <collision>
      <geometry>
        <cylinder length="2" radius="0.1"/>
      </geometry>
    </collision>
    <inertial>
      <mass value="0.10"/>
      <inertia
        ixx="0.0002"
        iyy="0.0002"
        izz="0.0002"
        ixy="0"
        ixz="0"
        iyz="0"
      />
    </inertial>
  </link>

  <!-- Joints -->
  <joint name="base_to_sub_1" type="revolute">
    <parent link="base_link"/>
    <child link="sub_link_1"/>
    <axis xyz="0 1 0"/>
    <limit effort="10" upper="0" lower="10" velocity="1"/>
    <origin rpy="0 0 0" xyz="0 0.5 0"/>
  </joint>

  <joint name="base_to_sub_2" type="revolute">
    <parent link="base_link"/>
    <child link="sub_link_2"/>
    <axis xyz="0 1 0"/>
    <limit effort="10" upper="0" lower="10" velocity="1"/>
    <origin rpy="0 0 0" xyz="0 -0.5 0"/>
  </joint>
</robot>