<?xml version="1.0"?>
<robot name="first_robot">
  <link name="base_link">
    <visual>
      <geometry>
        <sphere radius="0.5" />
      </geometry>
    </visual>
    <collision>
      <geometry>
        <sphere radius="0.5" />
      </geometry>
    </collision>
    <inertial>
      <mass value="0.25" />
      <inertia ixx="0.0003" iyy="0.0003" izz="0.0003" ixy="0" ixz="0" iyz="0" />
    </inertial>
  </link>
  <link name="head">
    <visual>
      <origin xyz="0 0 0.3" rpy="0 0 0" />
      <geometry>
        <sphere radius="0.25" />
      </geometry>
    </visual>
    <collision>
      <origin xyz="0 0 0.3" rpy="0 0 0" />
      <geometry>
        <sphere radius="0.25" />
      </geometry>
    </collision>
    <inertial>
      <mass value="0.25" />
      <inertia ixx="0.0003" iyy="0.0003" izz="0.0003" ixy="0" ixz="0" iyz="0" />
    </inertial>
  </link>
  <link name="orb1">
    <visual>
      <origin xyz="0.75 0 0" rpy="0 0 0" />
      <geometry>
        <sphere radius="0.2" />
      </geometry>
    </visual>
    <collision>
      <origin xyz="0.75 0 0" rpy="0 0 0" />
      <geometry>
        <sphere radius="0.2" />
      </geometry>
    </collision>
    <inertial>
      <mass value="0.1" />
      <inertia ixx="0.0003" iyy="0.0003" izz="0.0003" ixy="0" ixz="0" iyz="0" />
    </inertial>
  </link>
  <link name="orb2">
    <visual>
      <origin xyz="0 0.75 0" rpy="0 0 0" />
      <geometry>
        <sphere radius="0.25" />
      </geometry>
    </visual>
    <collision>
      <origin xyz="0 0.75 0" rpy="0 0 0" />
      <geometry>
        <sphere radius="0.25" />
      </geometry>
    </collision>
    <inertial>
      <mass value="0.1" />
      <inertia ixx="0.0003" iyy="0.0003" izz="0.0003" ixy="0" ixz="0" iyz="0" />
    </inertial>
  </link>
  <link name="orb3">
    <visual>
      <origin xyz="-0.75 0 0" rpy="0 0 0" />
      <geometry>
        <sphere radius="0.25" />
      </geometry>
    </visual>
    <collision>
      <origin xyz="-0.75 0 0" rpy="0 0 0" />
      <geometry>
        <sphere radius="0.25" />
      </geometry>
    </collision>
    <inertial>
      <mass value="0.1" />
      <inertia ixx="0.0003" iyy="0.0003" izz="0.0003" ixy="0" ixz="0" iyz="0" />
    </inertial>
  </link>
  <link name="orb4">
    <visual>
      <origin xyz="0 -0.75 0" rpy="0 0 0" />
      <geometry>
        <sphere radius="0.25" />
      </geometry>
    </visual>
    <collision>
      <origin xyz="0 -0.75 0" rpy="0 0 0" />
      <geometry>
        <sphere radius="0.25" />
      </geometry>
    </collision>
    <inertial>
      <mass value="0.1" />
      <inertia ixx="0.0003" iyy="0.0003" izz="0.0003" ixy="0" ixz="0" iyz="0" />
    </inertial>
  </link>

  <joint name="base_to_head" type="revolute">
    <parent link="base_link"/>
    <child link="head"/>
    <axis xyz="0 0 1" />
    <limit effort="7" upper="0" lower="7" velocity="1" />
    <origin rpy="0 0 0" xyz="0 0 0.5" />
  </joint>
  <joint name="base_to_orb1" type="revolute">
    <parent link="base_link"/>
    <child link="orb1"/>
    <axis xyz="1 0 0" />
    <limit effort="7" upper="0" lower="7" velocity="1" />
    <origin rpy="0 0 0" xyz="0 0 0" />
  </joint>
  <joint name="base_to_orb2" type="revolute">
    <parent link="base_link"/>
    <child link="orb2"/>
    <axis xyz="1 1 0" />
    <limit effort="7" upper="0" lower="7" velocity="1" />
    <origin rpy="0 0 0" xyz="0 0 0" />
  </joint>
  <joint name="base_to_orb3" type="revolute">
    <parent link="base_link"/>
    <child link="orb3"/>
    <axis xyz="0 1 0" />
    <limit effort="7" upper="0" lower="7" velocity="1" />
    <origin rpy="0 0 0" xyz="0 0 0" />
  </joint>
  <joint name="base_to_orb4" type="revolute">
    <parent link="base_link"/>
    <child link="orb4"/>
    <axis xyz="0 1 1" />
    <limit effort="7" upper="0" lower="7" velocity="1" />
    <origin rpy="0 0 0" xyz="0 0 0" />
  </joint>
</robot>