<?xml version="1.0"?>
<robot name="myfirst">
<!-- Material Colours -->
  <material name="blue">
    <color rgba="0 0 0.8 1"/>
  </material>
  <material name="black">
    <color rgba="0 0 0 1"/>
  </material>
  <material name="red">
    <color rgba="1 0 0 1"/>
  </material>
  <material name="green">
    <color rgba="0 1 0 1"/>
  </material>
  <material name="sky_blue">
    <color rgba="0 1 1 1"/>
  </material>

  <link name="base_link">
    <visual>
      <geometry>
        <cylinder radius="0.25" length="0.6"/>
      </geometry>
      <material name="sky_blue"/>
    </visual>
    <collision>
      <geometry>
        <cylinder radius="0.25" length="0.6"/>
      </geometry>
    </collision>
    <inertial>
      <mass value="0.25"/>
      <inertia ixx="0.0003" ixy="0.0" ixz="0.0" iyy="0.0003" iyz="0.0" izz="0.0003"/>
    </inertial>
  </link> 

  <link name="sub_link">
    <visual>
      <geometry>
        <cylinder radius="0.1" length="1"/>
      </geometry>
      <material name="green"/>
    </visual>
    <collision>
      <geometry>
        <cylinder radius="0.1" length="1"/>
      </geometry>
    </collision>
    <inertial>
      <mass value="0.25"/>
      <inertia ixx="0.0003" ixy="0.0" ixz="0.0" iyy="0.0003" iyz="0.0" izz="0.0003"/>
    </inertial>
  </link> 

  <joint name="base_to_sub" type="revolute">
    <parent link="base_link"/>
    <child link="sub_link"/>
    <axis xyz="1 0.0 0.0"/>
    <limit lower="10" upper="0.0" effort="10" velocity="1"/>
    <origin rpy="0.0 0.0 0.0" xyz="0.0 0.5 0.0"/>
  </joint>
</robot>